<mujoco model="inverted pendulum">
  <compiler inertiafromgeom="true"/>
  <default>
    <joint armature="0" damping="1" limited="true"/>
    <geom contype="0" friction="1 0.1 0.1" rgba="0.4 0.33 0.26 1.0"/>
    <tendon/>
    <motor ctrlrange="-3 3"/>
  </default>
  <option gravity="0 0 -9.81" timestep="0.02" />
  <custom>
    <!-- brax custom params -->
    <numeric data="10000" name="constraint_stiffness"/>
    <numeric data="10000" name="constraint_limit_stiffness"/>
    <numeric data="0" name="spring_mass_scale"/>
    <numeric data="1" name="spring_inertia_scale"/>
    <numeric data="5" name="solver_maxls"/>
  </custom>
  <size nstack="3000"/>
  <worldbody>
    <light diffuse=".5 .5 .5" pos="0 0 3" dir="0 0 -1"/>
    <!--geom name="ground" type="plane" pos="0 0 0" /-->
    <geom name="rail" pos="0 0 0" quat="0.707 0 0.707 0" size="0.02 1" type="capsule" rgba="1 1 1 1"/>
    <body name="cart" pos="0 0 0">
      <joint axis="1 0 0" limited="true" name="slider" pos="0 0 0" range="-1 1" type="slide"/>
      <geom name="cart" pos="0 0 0" quat="0.707 0 0.707 0" size="0.1 0.1" type="capsule"/>
      <body name="pole" pos="0 0 0">
        <joint axis="0 1 0" name="hinge" pos="0 0 0" range="-90 90" type="hinge"/>
        <geom fromto="0 0 0 0.001 0 0.6" name="cpole" size="0.049 0.3" type="capsule"/>
        <!--                 <body name="pole2" pos="0.001 0 0.6"><joint name="hinge2" type="hinge" pos="0 0 0" axis="0 1 0"/><geom name="cpole2" type="capsule" fromto="0 0 0 0 0 0.6" size="0.05 0.3" rgba="0.7 0 0.7 1"/><site name="tip2" pos="0 0 .6"/></body>-->
      </body>
    </body>
  </worldbody>
  <actuator>
    <motor ctrllimited="true" ctrlrange="-3 3" gear="100" joint="slider" name="slide"/>
  </actuator>
</mujoco>