<mujoco model="walker2d">
  <compiler angle="radian" autolimits="true"/>
  <default>
    <joint limited="true" armature="0.01" damping="0.1"/>
    <geom contype="0" conaffinity="0" friction="0.7 0.1 0.1" rgba="0.4 0.33 0.26 1.0"/>
  </default>
  <!-- Removed RK4 integrator for brax. -->
  <option timestep="0.002" iterations="4" />
  <custom>
    <!-- brax custom params -->
    <numeric data="5000" name="constraint_limit_stiffness"/>
    <numeric data="10000" name="constraint_stiffness"/>
    <numeric data="20" name="constraint_ang_damping"/>
    <numeric data="1" name="vel_damping"/>
    <numeric data="-0.05" name="ang_damping"/>
    <numeric data="0" name="spring_mass_scale"/>
    <numeric data="1" name="spring_inertia_scale"/>
    <numeric data="15" name="solver_maxls"/>
    <numeric data="20" name="matrix_inv_iterations"/>
  </custom>
  <worldbody>
    <geom name="floor" size="40 40 40" type="plane" conaffinity="1" material="MatPlane"/>
    <light pos="0 0 1.3" dir="0 0 -1" directional="true" cutoff="100" exponent="1" diffuse="1 1 1" specular="0.1 0.1 0.1"/>
    <body name="torso" pos="0 0 1.25">
      <!-- Brax does not support stacked joints at different locations, so we move rootx and rootz
        from (0, 0, 0) to the rooty position at (0, 0, 1.25). Joint ref was also removed. -->
      <joint name="rootx" pos="0 0 0" axis="1 0 0" limited="false" type="slide" armature="0" damping="0"/>
      <joint name="rootz" pos="0 0 0" axis="0 0 1" limited="false" type="slide" armature="0" damping="0"/>
      <joint name="rooty" pos="0 0 0" axis="0 1 0" limited="false" armature="0" damping="0"/>
      <geom name="torso_geom" size="0.05 0.2" type="capsule" contype="1" friction="0.9 0.1 0.1"/>
      <camera name="track" pos="0 -3 -0.25" quat="0.707107 0.707107 0 0" mode="trackcom"/>
      <body name="thigh" pos="0 0 -0.2">
        <joint name="thigh_joint" pos="0 0 0" axis="0 -1 0" range="-2.61799 0"/>
        <geom name="thigh_geom" size="0.05 0.225" pos="0 0 -0.225" type="capsule" friction="0.9 0.1 0.1"/>
        <body name="leg" pos="0 0 -0.7">
          <joint name="leg_joint" pos="0 0 0.25" axis="0 -1 0" range="-2.61799 0"/>
          <geom name="leg_geom" size="0.04 0.25" type="capsule" friction="0.9 0.1 0.1"/>
          <body name="foot" pos="0.2 0 -0.35">
            <joint name="foot_joint" pos="-0.2 0 0.1" axis="0 -1 0" range="-0.785398 0.785398"/>
            <geom name="foot_geom" size="0.06 0.1" pos="-0.1 0 0.1" quat="0.707107 0 -0.707107 0" type="capsule" contype="1" friction="0.9 0.1 0.1"/>
          </body>
        </body>
      </body>
      <body name="thigh_left" pos="0 0 -0.2">
        <joint name="thigh_left_joint" pos="0 0 0" axis="0 -1 0" range="-2.61799 0"/>
        <geom name="thigh_left_geom" size="0.05 0.225" pos="0 0 -0.225" type="capsule" friction="0.9 0.1 0.1"/>
        <body name="leg_left" pos="0 0 -0.7">
          <joint name="leg_left_joint" pos="0 0 0.25" axis="0 -1 0" range="-2.61799 0"/>
          <geom name="leg_left_geom" size="0.04 0.25" type="capsule" friction="0.9 0.1 0.1"/>
          <body name="foot_left" pos="0.2 0 -0.35">
            <joint name="foot_left_joint" pos="-0.2 0 0.1" axis="0 -1 0" range="-0.785398 0.785398"/>
            <geom name="foot_left_geom" size="0.06 0.1" pos="-0.1 0 0.1" quat="0.707107 0 -0.707107 0" type="capsule" contype="1" friction="1.9 0.1 0.1"/>
          </body>
        </body>
      </body>
    </body>
  </worldbody>
  <actuator>
    <!-- <motor joint="torso_joint" ctrlrange="-100.0 100.0" isctrllimited="true"/>-->
    <motor ctrlrange="-1.0 1.0" gear="100" joint="thigh_joint"/>
    <motor ctrlrange="-1.0 1.0" gear="100" joint="leg_joint"/>
    <motor ctrlrange="-1.0 1.0" gear="100" joint="foot_joint"/>
    <motor ctrlrange="-1.0 1.0" gear="100" joint="thigh_left_joint"/>
    <motor ctrlrange="-1.0 1.0" gear="100" joint="leg_left_joint"/>
    <motor ctrlrange="-1.0 1.0" gear="100" joint="foot_left_joint"/>
    <!-- <motor joint="finger2_rot" ctrlrange="-20.0 20.0" isctrllimited="true"/>-->
  </actuator>
  <asset>
      <texture type="skybox" builtin="gradient" rgb1=".4 .5 .6" rgb2="0 0 0"
          width="100" height="100"/>
      <texture builtin="flat" height="1278" mark="cross" markrgb="1 1 1" name="texgeom" random="0.01" rgb1="0.8 0.6 0.4" rgb2="0.8 0.6 0.4" type="cube" width="127"/>
      <texture builtin="checker" height="100" name="texplane" rgb1="0 0 0" rgb2="0.8 0.8 0.8" type="2d" width="100"/>
      <material name="MatPlane" reflectance="0.5" shininess="1" specular="1" texrepeat="60 60" texture="texplane"/>
      <material name="geom" texture="texgeom" texuniform="true"/>
  </asset>
</mujoco>
